Workbook

Sheet Báo cáo
A1: STT | B1: Tổ Hạ Tầng | C1: Số lượng NV | D1: SL mẫu cần đo i-Speed | E1: Đã thực hiện i-Speed | F1: Tỉ lệ hoàn thành i-Speed | G1: SL mẫu cần đo speedtest | H1: Đã thực hiện Speedtest (Theo tuần) | I1: Tỉ lệ hoàn thành Speedtest | J1: SL mẫu đo 5G Speedtest | K1: Tỉ lệ mẫu đo 5G/số mẫu đo SpeedTest (>60%/Tổ)
A2: 1 | B2: Bến Lức | C2: =COUNTIF('DS nhân viên Speedtest'!F:F,B2) -> 14 | D2: =C2*16 -> 224 | E2: ='Tổ Bến Lức'!M6 -> 110 | F2: =E2/D2 -> 0.49107143 | G2: =(C2*16) -> 224 | H2: ='Tổ Bến Lức'!N6 -> 101 | I2: =H2/G2 -> 0.45089286 | J2: ='Tổ Bến Lức'!O6 -> 67 | K2: ='Tổ Bến Lức'!O4 -> 0.66336634
A3: 2 | B3: Đức Hòa | C3: =COUNTIF('DS nhân viên Speedtest'!F:F,B3) -> 13 | D3: =C3*16 -> 208 | E3: ='Tổ Đức Hòa'!M6 -> 23 | F3: =E3/D3 -> 0.11057692 | G3: =(C3*16) -> 208 | H3: ='Tổ Đức Hòa'!N6 -> 21 | I3: =H3/G3 -> 0.10096154 | J3: ='Tổ Đức Hòa'!O6 -> 5 | K3: ='Tổ Đức Hòa'!O4 -> 0.23809524
A4: 3 | B4: Gò Dầu | C4: =COUNTIF('DS nhân viên Speedtest'!F:F,B4) -> 15 | D4: =C4*16 -> 240 | E4: ='Tổ Gò Dầu'!M6 -> 180 | F4: =E4/D4 -> 0.75 | G4: =(C4*16) -> 240 | H4: ='Tổ Gò Dầu'!N6 -> 180 | I4: =H4/G4 -> 0.75 | J4: ='Tổ Gò Dầu'!O6 -> 39 | K4: ='Tổ Gò Dầu'!O4 -> 0.21666667
A5: 4 | B5: Kiến Tường | C5: =COUNTIF('DS nhân viên Speedtest'!F:F,B5) -> 18 | D5: =C5*16 -> 288 | E5: ='Tổ Kiến Tường'!M6 -> 85 | F5: =E5/D5 -> 0.29513889 | G5: =(C5*16) -> 288 | H5: ='Tổ Kiến Tường'!N6 -> 84 | I5: =H5/G5 -> 0.29166667 | J5: ='Tổ Kiến Tường'!O6 -> 0 | K5: ='Tổ Kiến Tường'!O4 -> 0
A6: 5 | B6: Tân An | C6: =COUNTIF('DS nhân viên Speedtest'!F:F,B6) -> 14 | D6: =C6*16 -> 224 | E6: ='Tổ Tân An'!M6 -> 126 | F6: =E6/D6 -> 0.5625 | G6: =(C6*16) -> 224 | H6: ='Tổ Tân An'!N6 -> 126 | I6: =H6/G6 -> 0.5625 | J6: ='Tổ Tân An'!O6 -> 103 | K6: ='Tổ Tân An'!O4 -> 0.81746032
A7: 6 | B7: Tân Châu | C7: =COUNTIF('DS nhân viên Speedtest'!F:F,B7) -> 15 | D7: =C7*16 -> 240 | E7: ='Tổ Tân Châu'!M6 -> 67 | F7: =E7/D7 -> 0.27916667 | G7: =(C7*16) -> 240 | H7: ='Tổ Tân Châu'!N6 -> 68 | I7: =H7/G7 -> 0.28333333 | J7: ='Tổ Tân Châu'!O6 -> 22 | K7: ='Tổ Tân Châu'!O4 -> 0.32352941
A8: 7 | B8: Tân Ninh | C8: =COUNTIF('DS nhân viên Speedtest'!F:F,B8) -> 17 | D8: =C8*16 -> 272 | E8: ='Tổ Tân Ninh'!M6 -> 125 | F8: =E8/D8 -> 0.45955882 | G8: =(C8*16) -> 272 | H8: ='Tổ Tân Ninh'!N6 -> 125 | I8: =H8/G8 -> 0.45955882 | J8: ='Tổ Tân Ninh'!O6 -> 77 | K8: ='Tổ Tân Ninh'!O4 -> 0.54609929
B9: Tây Ninh | C9: =SUM(C2:C8) -> 106 | D9: =C9*16 -> 1696 | E9: =SUM(E2:E8) -> 716 | F9: =E9/D9 -> 0.42216981 | G9: =(C9*16) -> 1696 | H9: =SUM(H2:H8) -> 705 | I9: =H9/G9 -> 0.41568396 | J9: =SUM(J2:J8) -> 313 | K9: =IF(H9 = 0, 0, J9/H9) -> 0.44397163
A12: Ngày báo cáo | B12: =TEXT(DATE(YEAR(TODAY()),MONTH(TODAY()),1),"dd/mm/yyyy")&" - "&TEXT(TODAY(),"dd/mm/yyyy") -> 01/07/2026 - 18/07/2026

Sheet Thay đổi
A1: STT | B1: Đơn vị TTHT ( Cũ - bỏ trống nếu là NV mới) ) | C1: Tên Nhân Viên | D1: Email | E1: SĐT | F1: Link test kết quả mới ( Chỉ nhập khi chưa thực hiện lần đầu hoặc thay đổi thiết bị ) | G1: Đơn vị TTHT ( Mới ) | H1: Ngày thay đổi | I1: Lý do thay đổi | J1: Trạng thái hỗ trợ | K1: X
A2: 1
A3: 2
A4: 3
A5: 4
A6: 5
A7: 6 | J7: =IF(K7 = "x","Đã hỗ trợ xong", IF(C7<> "","Chưa hỗ trợ",""))
A8: 7 | J8: =IF(K8 = "x","Đã hỗ trợ xong", IF(C8<> "","Chưa hỗ trợ",""))
A9: 8 | J9: =IF(K9 = "x","Đã hỗ trợ xong", IF(C9<> "","Chưa hỗ trợ",""))
A10: 9 | J10: =IF(K10 = "x","Đã hỗ trợ xong", IF(C10<> "","Chưa hỗ trợ",""))
A11: 10 | J11: =IF(K11 = "x","Đã hỗ trợ xong", IF(C11<> "","Chưa hỗ trợ",""))
A12: 11 | J12: =IF(K12 = "x","Đã hỗ trợ xong", IF(C12<> "","Chưa hỗ trợ",""))
A13: 12 | J13: =IF(K13 = "x","Đã hỗ trợ xong", IF(C13<> "","Chưa hỗ trợ",""))
A14: 13 | J14: =IF(K14 = "x","Đã hỗ trợ xong", IF(C14<> "","Chưa hỗ trợ",""))
A15: 14 | J15: =IF(K15 = "x","Đã hỗ trợ xong", IF(C15<> "","Chưa hỗ trợ",""))
A16: 15 | J16: =IF(K16 = "x","Đã hỗ trợ xong", IF(C16<> "","Chưa hỗ trợ",""))
A17: 16 | J17: =IF(K17 = "x","Đã hỗ trợ xong", IF(C17<> "","Chưa hỗ trợ",""))
A18: 17 | J18: =IF(K18 = "x","Đã hỗ trợ xong", IF(C18<> "","Chưa hỗ trợ",""))
... A32: 31 | J32: =IF(K32 = "x","Đã hỗ trợ xong", IF(C32<> "","Chưa hỗ trợ",""))

Sheet KQ đo kiểm Speedtest
A1: Nhân viên | B1: Đơn vị | C1: Ngày đo | D1: Số điện thoại | E1: Device ID | F1: Thiết bị | G1: Nhà mạng | H1: Địa chỉ | I1: Download Mbps | J1: Upload Mbps | K1: Mẫu hợp lệ | L1: Máy hỗ trợ 5G | M1: Jitter (ms)
A2: Trương Đình Lợi_TNH | B2: VNPT TNH | C2: 46037 | D2: 914163199 | E2: 467432229 | F2: Galaxy S22 Ultra | G2: Vinaphone | H2: Tây Ninh | I2: 739.107 | J2: 88.205 | K2: TRUE | L2: Có | M2: Nguyên bản | N2: 46062 | O2: =LEFT(A2, LEN(A2) - 4) -> Trương Đình Lợi
A3: Phạm Nguyễn Quang Huy_LAN | B3: VNPT TNH | C3: 46037 | D3: 828926567 | E3: 493854272 | F3: 14T | G3: Vinaphone | H3: Long An | I3: 812.703 | J3: 161.881 | K3: FALSE | L3: Có | M3: Nguyên bản | N3: 46156 | O3: =LEFT(A3, LEN(A3) - 4) -> Phạm Nguyễn Quang Huy
A4: Phạm Nguyễn Quang Huy_LAN | B4: VNPT TNH | C4: 46037 | D4: 947245878 | E4: 493854272 | F4: 14T | G4: Vinaphone | H4: Long An | I4: 812.703 | J4: 161.881 | K4: FALSE | L4: Có | M4: Nguyên bản | N4: 46156 | O4: =LEFT(A4, LEN(A4) - 4) -> Phạm Nguyễn Quang Huy
A5: Nguyễn Hoàng Tuấn_LAN | B5: VNPT TNH | C5: 46037 | D5: 915282271 | E5: 437354149 | F5: Galaxy A54 | G5: Vinaphone | H5: Long An | I5: 90.274 | J5: 53.296 | K5: TRUE | L5: Có | M5: Nguyên bản | N5: 46145 | O5: =LEFT(A5, LEN(A5) - 4) -> Nguyễn Hoàng Tuấn
A6: Nguyễn Hoàng Tuấn_LAN | B6: VNPT TNH | C6: 46037 | D6: 915282271 | E6: 437354149 | F6: Galaxy A54 | G6: Vinaphone | H6: Long An | I6: 90.274 | J6: 53.296 | K6: TRUE | L6: Có | M6: Nguyên bản | N6: 46145 | O6: =LEFT(A6, LEN(A6) - 4) -> Nguyễn Hoàng Tuấn
A7: Hồ Chí Linh_LAN | B7: VNPT TNH | C7: 46037 | D7: 948557338 | E7: 515291346 | F7: HONOR 400 | G7: Vinaphone | H7: Long An | I7: 881.225 | J7: 68.958 | K7: TRUE | L7: Có | M7: Nguyên bản | N7: 46192 | O7: =LEFT(A7, LEN(A7) - 4) -> Hồ Chí Linh
A8: Đinh Phú Trung_LAN | B8: VNPT TNH | C8: 46037 | D8: 918606989 | E8: 438163315 | F8: Galaxy A33 5G | G8: Vinaphone | H8: Long An Province | I8: 33.385 | J8: 21.106 | K8: FALSE | L8: Có | M8: Nguyên bản | N8: 46026 | O8: =LEFT(A8, LEN(A8) - 4) -> Đinh Phú Trung
A9: Đinh Phú Trung_LAN | B9: VNPT TNH | C9: 46037 | D9: 918606989 | E9: 438163315 | F9: Galaxy A33 5G | G9: Vinaphone | H9: Long An Province | I9: 33.385 | J9: 21.106 | K9: FALSE | L9: Có | M9: Nguyên bản | N9: 46026 | O9: =LEFT(A9, LEN(A9) - 4) -> Đinh Phú Trung
A10: Trịnh Minh Trí_LAN | B10: VNPT TNH | C10: 46037 | D10: 918278345 | E10: 511526722 | F10: Galaxy A52s 5G | G10: Vinaphone | H10: Long An Province | I10: 47.502 | J10: 5.699 | K10: TRUE | L10: Có | M10: Nguyên bản | N10: 46027 | O10: =LEFT(A10, LEN(A10) - 4) -> Trịnh Minh Trí
A11: Đặng Ngọc Sơn_LAN | B11: VNPT TNH | C11: 46037 | D11: 949786476 | E11: 514815800 | F11: Redmi Note 12 4G | G11: Vinaphone | H11: Long An Province | I11: 89.407 | J11: 43.324 | K11: TRUE | L11: N/A | M11: Nguyên bản | N11: 46246 | O11: =LEFT(A11, LEN(A11) - 4) -> Đặng Ngọc Sơn
A12: Đỗ Tấn Phát_LAN | B12: VNPT TNH | C12: 46037 | D12: 917769763 | E12: 297808089 | F12: iPhone 12 Pro Max 5G | G12: Vinaphone | H12: Long An Province | I12: 63.557 | J12: 35.383 | K12: TRUE | L12: Có | M12: N/A | N12: 46085 | O12: =LEFT(A12, LEN(A12) - 4) -> Đỗ Tấn Phát
A13: Nguyễn Quang Trực_LAN | B13: VNPT TNH | C13: 46037 | D13: 944653959 | E13: 503405277 | G13: Vinaphone | H13: Long An | I13: 116.735 | J13: 23.001 | K13: FALSE | L13: N/A | M13: Nguyên bản | N13: 46027 | O13: =LEFT(A13, LEN(A13) - 4) -> Nguyễn Quang Trực
A14: Trịnh Minh Trí_LAN | B14: VNPT TNH | C14: 46037 | D14: 918278345 | E14: 511526722 | F14: Galaxy A52s 5G | G14: Vinaphone | H14: Long An Province | I14: 71.234 | J14: 40.429 | K14: TRUE | L14: Có | M14: Nguyên bản | N14: 46085 | O14: =LEFT(A14, LEN(A14) - 4) -> Trịnh Minh Trí
A15: Trịnh Minh Trí_LAN | B15: VNPT TNH | C15: 46037 | D15: 918278345 | E15: 511526722 | F15: Galaxy A52s 5G | G15: Vinaphone | H15: Long An Province | I15: 75.284 | J15: 41.919 | K15: TRUE | L15: Có | M15: Nguyên bản | N15: 43.8 | O15: =LEFT(A15, LEN(A15) - 4) -> Trịnh Minh Trí
A16: Đặng Hoàng Vũ_LAN | B16: VNPT TNH | C16: 46037 | D16: 918616787 | E16: 302371366 | F16: iPhone 12 Pro Max 5G | G16: Vinaphone | H16: Long An Province | I16: 45.479 | J16: 8.919 | K16: TRUE | L16: Có | M16: N/A | N16: 46060 | O16: =LEFT(A16, LEN(A16) - 4) -> Đặng Hoàng Vũ
A17: Đặng Hoàng Vũ_LAN | B17: VNPT TNH | C17: 46037 | D17: 918616787 | E17: 302371366 | F17: iPhone 12 Pro Max 5G | G17: Vinaphone | H17: Long An Province | I17: 45.479 | J17: 8.919 | K17: TRUE | L17: Có | M17: N/A | N17: 46060 | O17: =LEFT(A17, LEN(A17) - 4) -> Đặng Hoàng Vũ
A18: Trịnh Minh Trí_LAN | B18: VNPT TNH | C18: 46037 | D18: 918278345 | E18: 511526722 | F18: Galaxy A52s 5G | G18: Vinaphone | H18: Long An Province | I18: 65.792 | J18: 38.042 | K18: TRUE | L18: Có | M18: Nguyên bản | N18: 46026 | O18: =LEFT(A18, LEN(A18) - 4) -> Trịnh Minh Trí
A19: Trịnh Minh Trí_LAN | B19: VNPT TNH | C19: 46037 | D19: 918278345 | E19: 511526722 | F19: Galaxy A52s 5G | G19: Vinaphone | H19: Long An Province | I19: 64.399 | J19: 42.455 | K19: TRUE | L19: Có | M19: Nguyên bản | N19: 46025 | O19: =LEFT(A19, LEN(A19) - 4) -> Trịnh Minh Trí
A20: Dương Nhật Phương_LAN | B20: VNPT TNH | C20: 46037 | D20: 913352939 | E20: 511935418 | F20: Galaxy A55 | G20: Vinaphone | H20: Long An | I20: 603.624 | J20: 43.749 | K20: TRUE | L20: Có | M20: Nguyên bản | N20: 46106 | O20: =LEFT(A20, LEN(A20) - 4) -> Dương Nhật Phương
A21: Lê Thành Tài_TNH | B21: VNPT TNH | C21: 46037 | D21: 918955485 | E21: 463253403 | F21: GT Neo 5 | G21: Vinaphone | H21: Tây Ninh | I21: 67.186 | J21: 55.694 | K21: TRUE | L21: Có | M21: Nguyên bản | N21: 46209 | O21: =LEFT(A21, LEN(A21) - 4) -> Lê Thành Tài
A22: Lê Thành Tài_TNH | B22: VNPT TNH | C22: 46037 | D22: 918955485 | E22: 463253403 | F22: GT Neo 5 | G22: Vinaphone | H22: Tây Ninh | I22: 102.528 | J22: 41.901 | K22: TRUE | L22: Có | M22: Nguyên bản | N22: 46067 | O22: =LEFT(A22, LEN(A22) - 4) -> Lê Thành Tài
A23: Dương Nhật Phương_LAN | B23: VNPT TNH | C23: 46037 | D23: 913352939 | E23: 511935418 | F23: Galaxy A55 | G23: Vinaphone | H23: Long An | I23: 873.88 | J23: 135.755 | K23: TRUE | L23: Có | M23: Nguyên bản | N23: 46235 | O23: =LEFT(A23, LEN(A23) - 4) -> Dương Nhật Phương
A24: Võ Quang Duy_LAN | B24: VNPT TNH | C24: 46037 | D24: 945833826 | E24: 515016582 | F24: Galaxy S24 Ultra | G24: Vinaphone | H24: Long An | I24: 932.866 | J24: 130.39 | K24: TRUE | L24: Có | M24: Nguyên bản | N24: 46198 | O24: =LEFT(A24, LEN(A24) - 4) -> Võ Quang Duy
A25: Dương Nhật Phương_LAN | B25: VNPT TNH | C25: 46037 | D25: 913352939 | E25: 511935418 | F25: Galaxy A55 | G25: Vinaphone | H25: Long An | I25: 1054.134 | J25: 136.059 | K25: TRUE | L25: Có | M25: Nguyên bản | N25: 40.5 | O25: =LEFT(A25, LEN(A25) - 4) -> Dương Nhật Phương
A26: Dương Nhật Phương_LAN | B26: VNPT TNH | C26: 46037 | D26: 913352939 | E26: 511935418 | F26: Galaxy A55 | G26: Vinaphone | H26: Long An | I26: 1155.736 | J26: 53.503 | K26: TRUE | L26: Có | M26: Nguyên bản | N26: 46073 | O26: =LEFT(A26, LEN(A26) - 4) -> Dương Nhật Phương
A27: Dương Nhật Phương_LAN | B27: VNPT TNH | C27: 46037 | D27: 913352939 | E27: 511935418 | F27: Galaxy A55 | G27: Vinaphone | H27: Long An | I27: 801.992 | J27: 93.734 | K27: TRUE | L27: Có | M27: Nguyên bản | N27: 46223 | O27: =LEFT(A27, LEN(A27) - 4) -> Dương Nhật Phương
A28: Nguyễn Hữu Tân_LAN | B28: VNPT TNH | C28: 46037 | D28: 945663773 | E28: 507335872 | F28: Galaxy S10 | G28: Vinaphone | H28: Long An | I28: 54.86 | J28: 18.837 | K28: TRUE | L28: Không | M28: Rooted | N28: 46279 | O28: =LEFT(A28, LEN(A28) - 4) -> Nguyễn Hữu Tân
A29: Phù Hoàng Thành_LAN | B29: VNPT TNH | C29: 46037 | D29: 832428439 | E29: 494036091 | F29: Redmi Note 10 Pro | G29: Vinaphone | H29: Long An | I29: 57.967 | J29: 43.113 | K29: TRUE | L29: Không | M29: Nguyên bản | N29: 46026 | O29: =LEFT(A29, LEN(A29) - 4) -> Phù Hoàng Thành
A30: Phù Hoàng Thành_LAN | B30: VNPT TNH | C30: 46037 | D30: 852226484 | E30: 494036091 | F30: Redmi Note 10 Pro | G30: Vinaphone | H30: Long An | I30: 57.967 | J30: 43.113 | K30: TRUE | L30: Không | M30: Nguyên bản | N30: 46026 | O30: =LEFT(A30, LEN(A30) - 4) -> Phù Hoàng Thành
A31: Lê Minh Kha_LAN | B31: VNPT TNH | C31: 46037 | D31: 886313796 | E31: 408233038 | F31: 11T Pro | G31: Vinaphone | H31: Long An | I31: 198.851 | J31: 49.918 | K31: TRUE | L31: Có | M31: Nguyên bản | N31: 46146 | O31: =LEFT(A31, LEN(A31) - 4) -> Lê Minh Kha
A32: Lê Minh Kha_LAN | B32: VNPT TNH | C32: 46037 | D32: 829669739 | E32: 408233038 | F32: 11T Pro | G32: Vinaphone | H32: Long An | I32: 198.851 | J32: 49.918 | K32: TRUE | L32: Có | M32: Nguyên bản | N32: 46146 | O32: =LEFT(A32, LEN(A32) - 4) -> Lê Minh Kha
A33: Trần Minh Tuấn1_TNH | B33: VNPT TNH | C33: 46037 | D33: 918128333 | E33: 362213178 | F33: Reno5 5G | G33: Vinaphone | H33: Ho Chi Minh City | I33: 118.727 | J33: 55.155 | K33: TRUE | L33: Có | M33: Nguyên bản | N33: 46209 | O33: =LEFT(A33, LEN(A33) - 4) -> Trần Minh Tuấn1
A34: Huỳnh Phước Yên_LAN | B34: VNPT TNH | C34: 46037 | D34: 918611919 | E34: 321677895 | F34: iPhone 12 Pro Max 5G | G34: Vinaphone | H34: Long An | I34: 778.101 | J34: 129.646 | K34: TRUE | L34: Có | M34: N/A | N34: 46229 | O34: =LEFT(A34, LEN(A34) - 4) -> Huỳnh Phước Yên
A35: Nguyễn Thành Chí_LAN | B35: VNPT TNH | C35: 46037 | D35: 837012768 | E35: 276156622 | F35: iPhone 14 Pro Max | G35: Vinaphone | H35: Long An | I35: 600.473 | J35: 2.948 | K35: TRUE | L35: Có | M35: N/A | N35: 46220 | O35: =LEFT(A35, LEN(A35) - 4) -> Nguyễn Thành Chí
A36: Lê Hoàng Vinh_LAN | B36: VNPT TNH | C36: 46037 | D36: 917714086 | E36: 514807788 | F36: Unknown Device | G36: Vinaphone | H36: Long An | I36: 915.385 | J36: 93.205 | K36: TRUE | L36: Không | M36: Nguyên bản | N36: 46283 | O36: =LEFT(A36, LEN(A36) - 4) -> Lê Hoàng Vinh
A37: Lê Hoàng Vinh_LAN | B37: VNPT TNH | C37: 46037 | D37: 917714086 | E37: 514807788 | F37: Unknown Device | G37: Vinaphone | H37: Long An | I37: 28.373 | J37: 80.145 | K37: TRUE | L37: Không | M37: Nguyên bản | N37: 999.9 | O37: =LEFT(A37, LEN(A37) - 4) -> Lê Hoàng Vinh
A38: Đoàn Nguyễn Tuấn Anh_LAN | B38: VNPT TNH | C38: 46037 | D38: 943541776 | E38: 409462271 | F38: Galaxy A53 | G38: Vinaphone | H38: Ho Chi Minh City | I38: 74.74 | J38: 26.975 | K38: TRUE | L38: Có | M38: Nguyên bản | N38: 46119 | O38: =LEFT(A38, LEN(A38) - 4) -> Đoàn Nguyễn Tuấn Anh
A39: Đoàn Nguyễn Tuấn Anh_LAN | B39: VNPT TNH | C39: 46037 | D39: 943541776 | E39: 409462271 | F39: Galaxy A53 | G39: Vinaphone | H39: Ho Chi Minh City | I39: 90.664 | J39: 28.975 | K39: TRUE | L39: Có | M39: Nguyên bản | N39: 46235 | O39: =LEFT(A39, LEN(A39) - 4) -> Đoàn Nguyễn Tuấn Anh
A40: Đoàn Nguyễn Tuấn Anh_LAN | B40: VNPT TNH | C40: 46037 | D40: 943541776 | E40: 409462271 | F40: Galaxy A53 | G40: Vinaphone | H40: Ho Chi Minh City | I40: 90.554 | J40: 30.042 | K40: TRUE | L40: Có | M40: Nguyên bản | N40: 46162 | O40: =LEFT(A40, LEN(A40) - 4) -> Đoàn Nguyễn Tuấn Anh
...

Sheet Tổ Bến Lức
A1: TRUNG TÂM HẠ TẦNG Kỳ báo cáo: tháng 07 năm 2026 | M1: Kết quả đo (Không điền cột này) | O1: Tổng mẫu đã đo
O2: =COUNTA(J7:J294) -> 101
O3: Tỉ lệ mẫu đo 5G
O4: =IF(O2=0,0,O6/O2) -> 0.66336634
A5: STT | B5: Tổ Hạ Tầng | C5: Tên người thực hiện | D5: SĐT-TEST | E5: Email | F5: Lần đo | G5: Ngày đo DD/MM/YY | H5: i-Speed | J5: SpeedTest | L5: Ghi chú | M5: i-Speed | N5: SpeedTest | O5: 5G
H6: Tốc độ Download | I6: Tốc độ Upload | J6: Tốc độ Download | K6: Tốc độ Upload | M6: =SUM(M7:M470) -> 110 | N6: =SUM(N7:N470) -> 101 | O6: =SUM(O7:O999) -> 67
A7: =IF(INDIRECT("'DS nhân viên Speedtest'!B"& (2+QUOTIENT(ROW()-ROW($A$7),16)))="","",ROW()-ROW($A$7)+1) -> 1 | B7: =IF(A7="","","Tổ Hạ tầng " & 'Báo cáo'!B2) -> Tổ Hạ tầng Bến Lức | C7: =IF(A7="","",INDIRECT("'DS nhân viên Speedtest'!B"& (2+QUOTIENT(A7-1,16)))) -> Đinh Phú Trung | D7: =IF(A7="","",INDIRECT("'DS nhân viên Speedtest'!C"& (2+QUOTIENT(A7-1,16)))) -> 918606989 | E7: =IF(A7="","",INDIRECT("'DS nhân viên Speedtest'!D"& (2+QUOTIENT(A7-1,16)))) -> trungdp.lan@vnpt.vn | F7: =IF(A7="","","Lần "&(MOD(ROW()-ROW($A$7),16)+1)) -> Lần 1 | G7: 46204 | H7: 275 | I7: 57.5 | J7: 617 | K7: 58.1 | M7: =IF(B7="","",IF(OR(G7="",H7="",I7=""),0,1)) -> 1 | N7: =IF(B7="","",IF(OR(G7="",J7="",K7=""),0,1)) -> 1 | O7: =IF(B7="","",IF((J7-0)>200,1,0)) -> 1
A8: =IF(INDIRECT("'DS nhân viên Speedtest'!B"& (2+QUOTIENT(ROW()-ROW($A$7),16)))="","",ROW()-ROW($A$7)+1) -> 2 | B8: =IF(A8="","",B7) -> Tổ Hạ tầng Bến Lức | C8: =IF(A8="","",INDIRECT("'DS nhân viên Speedtest'!B"& (2+QUOTIENT(A8-1,16)))) -> Đinh Phú Trung | D8: =IF(A8="","",INDIRECT("'DS nhân viên Speedtest'!C"& (2+QUOTIENT(A8-1,16)))) -> 918606989 | E8: =IF(A8="","",INDIRECT("'DS nhân viên Speedtest'!D"& (2+QUOTIENT(A8-1,16)))) -> trungdp.lan@vnpt.vn | F8: =IF(A8="","","Lần "&(MOD(ROW()-ROW($A$7),16)+1)) -> Lần 2 | G8: 46204 | H8: 284 | I8: 48.6 | J8: 756 | K8: 44.7 | M8: =IF(B8="","",IF(OR(G8="",H8="",I8=""),0,1)) -> 1 | N8: =IF(B8="","",IF(OR(G8="",J8="",K8=""),0,1)) -> 1 | O8: =IF(B8="","",IF((J8-0)>200,1,0)) -> 1
A9: =IF(INDIRECT("'DS nhân viên Speedtest'!B"& (2+QUOTIENT(ROW()-ROW($A$7),16)))="","",ROW()-ROW($A$7)+1) -> 3 | B9: =IF(A9="","",B8) -> Tổ Hạ tầng Bến Lức | C9: =IF(A9="","",INDIRECT("'DS nhân viên Speedtest'!B"& (2+QUOTIENT(A9-1,16)))) -> Đinh Phú Trung | D9: =IF(A9="","",INDIRECT("'DS nhân viên Speedtest'!C"& (2+QUOTIENT(A9-1,16)))) -> 918606989 | E9: =IF(A9="","",INDIRECT("'DS nhân viên Speedtest'!D"& (2+QUOTIENT(A9-1,16)))) -> trungdp.lan@vnpt.vn | F9: =IF(A9="","","Lần "&(MOD(ROW()-ROW($A$7),16)+1)) -> Lần 3 | G9: 46205 | H9: 107 | I9: 31.4 | J9: 653 | K9: 31.4 | M9: =IF(B9="","",IF(OR(G9="",H9="",I9=""),0,1)) -> 1 | N9: =IF(B9="","",IF(OR(G9="",J9="",K9=""),0,1)) -> 1 | O9: =IF(B9="","",IF((J9-0)>200,1,0)) -> 1
A10: =IF(INDIRECT("'DS nhân viên Speedtest'!B"& (2+QUOTIENT(ROW()-ROW($A$7),16)))="","",ROW()-ROW($A$7)+1) -> 4 | B10: =IF(A10="","",B9) -> Tổ Hạ tầng Bến Lức | C10: =IF(A10="","",INDIRECT("'DS nhân viên Speedtest'!B"& (2+QUOTIENT(A10-1,16)))) -> Đinh Phú Trung | D10: =IF(A10="","",INDIRECT("'DS nhân viên Speedtest'!C"& (2+QUOTIENT(A10-1,16)))) -> 918606989 | E10: =IF(A10="","",INDIRECT("'DS nhân viên Speedtest'!D"& (2+QUOTIENT(A10-1,16)))) -> trungdp.lan@vnpt.vn | F10: =IF(A10="","","Lần "&(MOD(ROW()-ROW($A$7),16)+1)) -> Lần 4 | G10: 46205 | H10: 112 | I10: 31.2 | J10: 692 | K10: 45.1 | M10: =IF(B10="","",IF(OR(G10="",H10="",I10=""),0,1)) -> 1 | N10: =IF(B10="","",IF(OR(G10="",J10="",K10=""),0,1)) -> 1 | O10: =IF(B10="","",IF((J10-0)>200,1,0)) -> 1
A11: =IF(INDIRECT("'DS nhân viên Speedtest'!B"& (2+QUOTIENT(ROW()-ROW($A$7),16)))="","",ROW()-ROW($A$7)+1) -> 5 | B11: =IF(A11="","",B10) -> Tổ Hạ tầng Bến Lức | C11: =IF(A11="","",INDIRECT("'DS nhân viên Speedtest'!B"& (2+QUOTIENT(A11-1,16)))) -> Đinh Phú Trung | D11: =IF(A11="","",INDIRECT("'DS nhân viên Speedtest'!C"& (2+QUOTIENT(A11-1,16)))) -> 918606989 | E11: =IF(A11="","",INDIRECT("'DS nhân viên Speedtest'!D"& (2+QUOTIENT(A11-1,16)))) -> trungdp.lan@vnpt.vn | F11: =IF(A11="","","Lần "&(MOD(ROW()-ROW($A$7),16)+1)) -> Lần 5 | G11: 46205 | H11: 109 | I11: 34 | J11: 748 | K11: 42.7 | M11: =IF(B11="","",IF(OR(G11="",H11="",I11=""),0,1)) -> 1 | N11: =IF(B11="","",IF(OR(G11="",J11="",K11=""),0,1)) -> 1 | O11: =IF(B11="","",IF((J11-0)>200,1,0)) -> 1
A12: =IF(INDIRECT("'DS nhân viên Speedtest'!B"& (2+QUOTIENT(ROW()-ROW($A$7),16)))="","",ROW()-ROW($A$7)+1) -> 6 | B12: =IF(A12="","",B11) -> Tổ Hạ tầng Bến Lức | C12: =IF(A12="","",INDIRECT("'DS nhân viên Speedtest'!B"& (2+QUOTIENT(A12-1,16)))) -> Đinh Phú Trung | D12: =IF(A12="","",INDIRECT("'DS nhân viên Speedtest'!C"& (2+QUOTIENT(A12-1,16)))) -> 918606989 | E12: =IF(A12="","",INDIRECT("'DS nhân viên Speedtest'!D"& (2+QUOTIENT(A12-1,16)))) -> trungdp.lan@vnpt.vn | F12: =IF(A12="","","Lần "&(MOD(ROW()-ROW($A$7),16)+1)) -> Lần 6 | G12: 46205 | H12: 76.4 | I12: 34 | J12: 748 | K12: 45.4 | M12: =IF(B12="","",IF(OR(G12="",H12="",I12=""),0,1)) -> 1 | N12: =IF(B12="","",IF(OR(G12="",J12="",K12=""),0,1)) -> 1 | O12: =IF(B12="","",IF((J12-0)>200,1,0)) -> 1
A13: =IF(INDIRECT("'DS nhân viên Speedtest'!B"& (2+QUOTIENT(ROW()-ROW($A$7),16)))="","",ROW()-ROW($A$7)+1) -> 7 | B13: =IF(A13="","",B12) -> Tổ Hạ tầng Bến Lức | C13: =IF(A13="","",INDIRECT("'DS nhân viên Speedtest'!B"& (2+QUOTIENT(A13-1,16)))) -> Đinh Phú Trung | D13: =IF(A13="","",INDIRECT("'DS nhân viên Speedtest'!C"& (2+QUOTIENT(A13-1,16)))) -> 918606989 | E13: =IF(A13="","",INDIRECT("'DS nhân viên Speedtest'!D"& (2+QUOTIENT(A13-1,16)))) -> trungdp.lan@vnpt.vn | F13: =IF(A13="","","Lần "&(MOD(ROW()-ROW($A$7),16)+1)) -> Lần 7 | G13: 46208 | H13: 78 | I13: 14 | J13: 73 | K13: 11 | M13: =IF(B13="","",IF(OR(G13="",H13="",I13=""),0,1)) -> 1 | N13: =IF(B13="","",IF(OR(G13="",J13="",K13=""),0,1)) -> 1 | O13: =IF(B13="","",IF((J13-0)>200,1,0)) -> 0
A14: =IF(INDIRECT("'DS nhân viên Speedtest'!B"& (2+QUOTIENT(ROW()-ROW($A$7),16)))="","",ROW()-ROW($A$7)+1) -> 8 | B14: =IF(A14="","",B13) -> Tổ Hạ tầng Bến Lức | C14: =IF(A14="","",INDIRECT("'DS nhân viên Speedtest'!B"& (2+QUOTIENT(A14-1,16)))) -> Đinh Phú Trung | D14: =IF(A14="","",INDIRECT("'DS nhân viên Speedtest'!C"& (2+QUOTIENT(A14-1,16)))) -> 918606989 | E14: =IF(A14="","",INDIRECT("'DS nhân viên Speedtest'!D"& (2+QUOTIENT(A14-1,16)))) -> trungdp.lan@vnpt.vn | F14: =IF(A14="","","Lần "&(MOD(ROW()-ROW($A$7),16)+1)) -> Lần 8 | G14: 46209 | H14: 132 | I14: 21 | J14: 100 | K14: 14 | M14: =IF(B14="","",IF(OR(G14="",H14="",I14=""),0,1)) -> 1 | N14: =IF(B14="","",IF(OR(G14="",J14="",K14=""),0,1)) -> 1 | O14: =IF(B14="","",IF((J14-0)>200,1,0)) -> 0
A15: =IF(INDIRECT("'DS nhân viên Speedtest'!B"& (2+QUOTIENT(ROW()-ROW($A$7),16)))="","",ROW()-ROW($A$7)+1) -> 9 | B15: =IF(A15="","",B14) -> Tổ Hạ tầng Bến Lức | C15: =IF(A15="","",INDIRECT("'DS nhân viên Speedtest'!B"& (2+QUOTIENT(A15-1,16)))) -> Đinh Phú Trung | D15: =IF(A15="","",INDIRECT("'DS nhân viên Speedtest'!C"& (2+QUOTIENT(A15-1,16)))) -> 918606989 | E15: =IF(A15="","",INDIRECT("'DS nhân viên Speedtest'!D"& (2+QUOTIENT(A15-1,16)))) -> trungdp.lan@vnpt.vn | F15: =IF(A15="","","Lần "&(MOD(ROW()-ROW($A$7),16)+1)) -> Lần 9 | G15: 46209 | H15: 107 | I15: 15 | J15: 98 | K15: 21 | M15: =IF(B15="","",IF(OR(G15="",H15="",I15=""),0,1)) -> 1 | N15: =IF(B15="","",IF(OR(G15="",J15="",K15=""),0,1)) -> 1 | O15: =IF(B15="","",IF((J15-0)>200,1,0)) -> 0
A16: =IF(INDIRECT("'DS nhân viên Speedtest'!B"& (2+QUOTIENT(ROW()-ROW($A$7),16)))="","",ROW()-ROW($A$7)+1) -> 10 | B16: =IF(A16="","",B15) -> Tổ Hạ tầng Bến Lức | C16: =IF(A16="","",INDIRECT("'DS nhân viên Speedtest'!B"& (2+QUOTIENT(A16-1,16)))) -> Đinh Phú Trung | D16: =IF(A16="","",INDIRECT("'DS nhân viên Speedtest'!C"& (2+QUOTIENT(A16-1,16)))) -> 918606989 | E16: =IF(A16="","",INDIRECT("'DS nhân viên Speedtest'!D"& (2+QUOTIENT(A16-1,16)))) -> trungdp.lan@vnpt.vn | F16: =IF(A16="","","Lần "&(MOD(ROW()-ROW($A$7),16)+1)) -> Lần 10 | G16: 46209 | H16: 77 | I16: 46 | J16: 82 | K16: 13 | M16: =IF(B16="","",IF(OR(G16="",H16="",I16=""),0,1)) -> 1 | N16: =IF(B16="","",IF(OR(G16="",J16="",K16=""),0,1)) -> 1 | O16: =IF(B16="","",IF((J16-0)>200,1,0)) -> 0
A17: =IF(INDIRECT("'DS nhân viên Speedtest'!B"& (2+QUOTIENT(ROW()-ROW($A$7),16)))="","",ROW()-ROW($A$7)+1) -> 11 | B17: =IF(A17="","",B16) -> Tổ Hạ tầng Bến Lức | C17: =IF(A17="","",INDIRECT("'DS nhân viên Speedtest'!B"& (2+QUOTIENT(A17-1,16)))) -> Đinh Phú Trung | D17: =IF(A17="","",INDIRECT("'DS nhân viên Speedtest'!C"& (2+QUOTIENT(A17-1,16)))) -> 918606989 | E17: =IF(A17="","",INDIRECT("'DS nhân viên Speedtest'!D"& (2+QUOTIENT(A17-1,16)))) -> trungdp.lan@vnpt.vn | F17: =IF(A17="","","Lần "&(MOD(ROW()-ROW($A$7),16)+1)) -> Lần 11 | G17: 46209 | H17: 95 | I17: 53 | J17: 93 | K17: 47 | M17: =IF(B17="","",IF(OR(G17="",H17="",I17=""),0,1)) -> 1 | N17: =IF(B17="","",IF(OR(G17="",J17="",K17=""),0,1)) -> 1 | O17: =IF(B17="","",IF((J17-0)>200,1,0)) -> 0
A18: =IF(INDIRECT("'DS nhân viên Speedtest'!B"& (2+QUOTIENT(ROW()-ROW($A$7),16)))="","",ROW()-ROW($A$7)+1) -> 12 | B18: =IF(A18="","",B17) -> Tổ Hạ tầng Bến Lức | C18: =IF(A18="","",INDIRECT("'DS nhân viên Speedtest'!B"& (2+QUOTIENT(A18-1,16)))) -> Đinh Phú Trung | D18: =IF(A18="","",INDIRECT("'DS nhân viên Speedtest'!C"& (2+QUOTIENT(A18-1,16)))) -> 918606989 | E18: =IF(A18="","",INDIRECT("'DS nhân viên Speedtest'!D"& (2+QUOTIENT(A18-1,16)))) -> trungdp.lan@vnpt.vn | F18: =IF(A18="","","Lần "&(MOD(ROW()-ROW($A$7),16)+1)) -> Lần 12 | M18: =IF(B18="","",IF(OR(G18="",H18="",I18=""),0,1)) -> 0 | N18: =IF(B18="","",IF(OR(G18="",J18="",K18=""),0,1)) -> 0 | O18: =IF(B18="","",IF((J18-0)>200,1,0)) -> 0
A19: =IF(INDIRECT("'DS nhân viên Speedtest'!B"& (2+QUOTIENT(ROW()-ROW($A$7),16)))="","",ROW()-ROW($A$7)+1) -> 13 | B19: =IF(A19="","",B18) -> Tổ Hạ tầng Bến Lức | C19: =IF(A19="","",INDIRECT("'DS nhân viên Speedtest'!B"& (2+QUOTIENT(A19-1,16)))) -> Đinh Phú Trung | D19: =IF(A19="","",INDIRECT("'DS nhân viên Speedtest'!C"& (2+QUOTIENT(A19-1,16)))) -> 918606989 | E19: =IF(A19="","",INDIRECT("'DS nhân viên Speedtest'!D"& (2+QUOTIENT(A19-1,16)))) -> trungdp.lan@vnpt.vn | F19: =IF(A19="","","Lần "&(MOD(ROW()-ROW($A$7),16)+1)) -> Lần 13 | M19: =IF(B19="","",IF(OR(G19="",H19="",I19=""),0,1)) -> 0 | N19: =IF(B19="","",IF(OR(G19="",J19="",K19=""),0,1)) -> 0 | O19: =IF(B19="","",IF((J19-0)>200,1,0)) -> 0
A20: =IF(INDIRECT("'DS nhân viên Speedtest'!B"& (2+QUOTIENT(ROW()-ROW($A$7),16)))="","",ROW()-ROW($A$7)+1) -> 14 | B20: =IF(A20="","",B19) -> Tổ Hạ tầng Bến Lức | C20: =IF(A20="","",INDIRECT("'DS nhân viên Speedtest'!B"& (2+QUOTIENT(A20-1,16)))) -> Đinh Phú Trung | D20: =IF(A20="","",INDIRECT("'DS nhân viên Speedtest'!C"& (2+QUOTIENT(A20-1,16)))) -> 918606989 | E20: =IF(A20="","",INDIRECT("'DS nhân viên Speedtest'!D"& (2+QUOTIENT(A20-1,16)))) -> trungdp.lan@vnpt.vn | F20: =IF(A20="","","Lần "&(MOD(ROW()-ROW($A$7),16)+1)) -> Lần 14 | M20: =IF(B20="","",IF(OR(G20="",H20="",I20=""),0,1)) -> 0 | N20: =IF(B20="","",IF(OR(G20="",J20="",K20=""),0,1)) -> 0 | O20: =IF(B20="","",IF((J20-0)>200,1,0)) -> 0
A21: =IF(INDIRECT("'DS nhân viên Speedtest'!B"& (2+QUOTIENT(ROW()-ROW($A$7),16)))="","",ROW()-ROW($A$7)+1) -> 15 | B21: =IF(A21="","",B20) -> Tổ Hạ tầng Bến Lức | C21: =IF(A21="","",INDIRECT("'DS nhân viên Speedtest'!B"& (2+QUOTIENT(A21-1,16)))) -> Đinh Phú Trung | D21: =IF(A21="","",INDIRECT("'DS nhân viên Speedtest'!C"& (2+QUOTIENT(A21-1,16)))) -> 918606989 | E21: =IF(A21="","",INDIRECT("'DS nhân viên Speedtest'!D"& (2+QUOTIENT(A21-1,16)))) -> trungdp.lan@vnpt.vn | F21: =IF(A21="","","Lần "&(MOD(ROW()-ROW($A$7),16)+1)) -> Lần 15 | M21: =IF(B21="","",IF(OR(G21="",H21="",I21=""),0,1)) -> 0 | N21: =IF(B21="","",IF(OR(G21="",J21="",K21=""),0,1)) -> 0 | O21: =IF(B21="","",IF((J21-0)>200,1,0)) -> 0
A22: =IF(INDIRECT("'DS nhân viên Speedtest'!B"& (2+QUOTIENT(ROW()-ROW($A$7),16)))="","",ROW()-ROW($A$7)+1) -> 16 | B22: =IF(A22="","",B21) -> Tổ Hạ tầng Bến Lức | C22: =IF(A22="","",INDIRECT("'DS nhân viên Speedtest'!B"& (2+QUOTIENT(A22-1,16)))) -> Đinh Phú Trung | D22: =IF(A22="","",INDIRECT("'DS nhân viên Speedtest'!C"& (2+QUOTIENT(A22-1,16)))) -> 918606989 | E22: =IF(A22="","",INDIRECT("'DS nhân viên Speedtest'!D"& (2+QUOTIENT(A22-1,16)))) -> trungdp.lan@vnpt.vn | F22: =IF(A22="","","Lần "&(MOD(ROW()-ROW($A$7),16)+1)) -> Lần 16 | M22: =IF(B22="","",IF(OR(G22="",H22="",I22=""),0,1)) -> 0 | N22: =IF(B22="","",IF(OR(G22="",J22="",K22=""),0,1)) -> 0 | O22: =IF(B22="","",IF((J22-0)>200,1,0)) -> 0
A23: =IF(INDIRECT("'DS nhân viên Speedtest'!B"& (2+QUOTIENT(ROW()-ROW($A$7),16)))="","",ROW()-ROW($A$7)+1) -> 17 | B23: =IF(A23="","",B22) -> Tổ Hạ tầng Bến Lức | C23: =IF(A23="","",INDIRECT("'DS nhân viên Speedtest'!B"& (2+QUOTIENT(A23-1,16)))) -> Nguyễn Phước Lộc | D23: =IF(A23="","",INDIRECT("'DS nhân viên Speedtest'!C"& (2+QUOTIENT(A23-1,16)))) -> 813232338 | E23: =IF(A23="","",INDIRECT("'DS nhân viên Speedtest'!D"& (2+QUOTIENT(A23-1,16)))) -> locnp.lan@vnpt.vn | F23: =IF(A23="","","Lần "&(MOD(ROW()-ROW($A$7),16)+1)) -> Lần 1 | G23: 46205 | H23: 280 | I23: 78.9 | J23: 768 | K23: 93.0 | M23: =IF(B23="","",IF(OR(G23="",H23="",I23=""),0,1)) -> 1 | N23: =IF(B23="","",IF(OR(G23="",J23="",K23=""),0,1)) -> 1 | O23: =IF(B23="","",IF((J23-0)>200,1,0)) -> 1
A24: =IF(INDIRECT("'DS nhân viên Speedtest'!B"& (2+QUOTIENT(ROW()-ROW($A$7),16)))="","",ROW()-ROW($A$7)+1) -> 18 | B24: =IF(A24="","",B23) -> Tổ Hạ tầng Bến Lức | C24: =IF(A24="","",INDIRECT("'DS nhân viên Speedtest'!B"& (2+QUOTIENT(A24-1,16)))) -> Nguyễn Phước Lộc | D24: =IF(A24="","",INDIRECT("'DS nhân viên Speedtest'!C"& (2+QUOTIENT(A24-1,16)))) -> 813232338 | E24: =IF(A24="","",INDIRECT("'DS nhân viên Speedtest'!D"& (2+QUOTIENT(A24-1,16)))) -> locnp.lan@vnpt.vn | F24: =IF(A24="","","Lần "&(MOD(ROW()-ROW($A$7),16)+1)) -> Lần 2 | G24: 46206 | H24: 332 | I24: 47.9 | J24: 657 | K24: 25.0 | M24: =IF(B24="","",IF(OR(G24="",H24="",I24=""),0,1)) -> 1 | N24: =IF(B24="","",IF(OR(G24="",J24="",K24=""),0,1)) -> 1 | O24: =IF(B24="","",IF((J24-0)>200,1,0)) -> 1
A25: =IF(INDIRECT("'DS nhân viên Speedtest'!B"& (2+QUOTIENT(ROW()-ROW($A$7),16)))="","",ROW()-ROW($A$7)+1) -> 19 | B25: =IF(A25="","",B24) -> Tổ Hạ tầng Bến Lức | C25: =IF(A25="","",INDIRECT("'DS nhân viên Speedtest'!B"& (2+QUOTIENT(A25-1,16)))) -> Nguyễn Phước Lộc | D25: =IF(A25="","",INDIRECT("'DS nhân viên Speedtest'!C"& (2+QUOTIENT(A25-1,16)))) -> 813232338 | E25: =IF(A25="","",INDIRECT("'DS nhân viên Speedtest'!D"& (2+QUOTIENT(A25-1,16)))) -> locnp.lan@vnpt.vn | F25: =IF(A25="","","Lần "&(MOD(ROW()-ROW($A$7),16)+1)) -> Lần 3 | G25: 46209 | H25: 311 | I25: 47.6 | J25: 747 | K25: 34.5 | M25: =IF(B25="","",IF(OR(G25="",H25="",I25=""),0,1)) -> 1 | N25: =IF(B25="","",IF(OR(G25="",J25="",K25=""),0,1)) -> 1 | O25: =IF(B25="","",IF((J25-0)>200,1,0)) -> 1
A26: =IF(INDIRECT("'DS nhân viên Speedtest'!B"& (2+QUOTIENT(ROW()-ROW($A$7),16)))="","",ROW()-ROW($A$7)+1) -> 20 | B26: =IF(A26="","",B25) -> Tổ Hạ tầng Bến Lức | C26: =IF(A26="","",INDIRECT("'DS nhân viên Speedtest'!B"& (2+QUOTIENT(A26-1,16)))) -> Nguyễn Phước Lộc | D26: =IF(A26="","",INDIRECT("'DS nhân viên Speedtest'!C"& (2+QUOTIENT(A26-1,16)))) -> 813232338 | E26: =IF(A26="","",INDIRECT("'DS nhân viên Speedtest'!D"& (2+QUOTIENT(A26-1,16)))) -> locnp.lan@vnpt.vn | F26: =IF(A26="","","Lần "&(MOD(ROW()-ROW($A$7),16)+1)) -> Lần 4 | G26: 46209 | H26: 322 | I26: 93.0 | J26: 1100 | K26: 121 | M26: =IF(B26="","",IF(OR(G26="",H26="",I26=""),0,1)) -> 1 | N26: =IF(B26="","",IF(OR(G26="",J26="",K26=""),0,1)) -> 1 | O26: =IF(B26="","",IF((J26-0)>200,1,0)) -> 1
A27: =IF(INDIRECT("'DS nhân viên Speedtest'!B"& (2+QUOTIENT(ROW()-ROW($A$7),16)))="","",ROW()-ROW($A$7)+1) -> 21 | B27: =IF(A27="","",B26) -> Tổ Hạ tầng Bến Lức | C27: =IF(A27="","",INDIRECT("'DS nhân viên Speedtest'!B"& (2+QUOTIENT(A27-1,16)))) -> Nguyễn Phước Lộc | D27: =IF(A27="","",INDIRECT("'DS nhân viên Speedtest'!C"& (2+QUOTIENT(A27-1,16)))) -> 813232338 | E27: =IF(A27="","",INDIRECT("'DS nhân viên Speedtest'!D"& (2+QUOTIENT(A27-1,16)))) -> locnp.lan@vnpt.vn | F27: =IF(A27="","","Lần "&(MOD(ROW()-ROW($A$7),16)+1)) -> Lần 5 | G27: 46210 | H27: 309 | I27: 83.6 | J27: 929 | K27: 143 | M27: =IF(B27="","",IF(OR(G27="",H27="",I27=""),0,1)) -> 1 | N27: =IF(B27="","",IF(OR(G27="",J27="",K27=""),0,1)) -> 1 | O27: =IF(B27="","",IF((J27-0)>200,1,0)) -> 1
A28: =IF(INDIRECT("'DS nhân viên Speedtest'!B"& (2+QUOTIENT(ROW()-ROW($A$7),16)))="","",ROW()-ROW($A$7)+1) -> 22 | B28: =IF(A28="","",B27) -> Tổ Hạ tầng Bến Lức | C28: =IF(A28="","",INDIRECT("'DS nhân viên Speedtest'!B"& (2+QUOTIENT(A28-1,16)))) -> Nguyễn Phước Lộc | D28: =IF(A28="","",INDIRECT("'DS nhân viên Speedtest'!C"& (2+QUOTIENT(A28-1,16)))) -> 813232338 | E28: =IF(A28="","",INDIRECT("'DS nhân viên Speedtest'!D"& (2+QUOTIENT(A28-1,16)))) -> locnp.lan@vnpt.vn | F28: =IF(A28="","","Lần "&(MOD(ROW()-ROW($A$7),16)+1)) -> Lần 6 | G28: 46210 | H28: 293 | I28: 42.1 | J28: 763 | K28: 57.9 | M28: =IF(B28="","",IF(OR(G28="",H28="",I28=""),0,1)) -> 1 | N28: =IF(B28="","",IF(OR(G28="",J28="",K28=""),0,1)) -> 1 | O28: =IF(B28="","",IF((J28-0)>200,1,0)) -> 1
A29: =IF(INDIRECT("'DS nhân viên Speedtest'!B"& (2+QUOTIENT(ROW()-ROW($A$7),16)))="","",ROW()-ROW($A$7)+1) -> 23 | B29: =IF(A29="","",B28) -> Tổ Hạ tầng Bến Lức | C29: =IF(A29="","",INDIRECT("'DS nhân viên Speedtest'!B"& (2+QUOTIENT(A29-1,16)))) -> Nguyễn Phước Lộc | D29: =IF(A29="","",INDIRECT("'DS nhân viên Speedtest'!C"& (2+QUOTIENT(A29-1,16)))) -> 813232338 | E29: =IF(A29="","",INDIRECT("'DS nhân viên Speedtest'!D"& (2+QUOTIENT(A29-1,16)))) -> locnp.lan@vnpt.vn | F29: =IF(A29="","","Lần "&(MOD(ROW()-ROW($A$7),16)+1)) -> Lần 7 | G29: 46210 | H29: 283 | I29: 54.4 | J29: 799 | K29: 52.3 | M29: =IF(B29="","",IF(OR(G29="",H29="",I29=""),0,1)) -> 1 | N29: =IF(B29="","",IF(OR(G29="",J29="",K29=""),0,1)) -> 1 | O29: =IF(B29="","",IF((J29-0)>200,1,0)) -> 1
A30: =IF(INDIRECT("'DS nhân viên Speedtest'!B"& (2+QUOTIENT(ROW()-ROW($A$7),16)))="","",ROW()-ROW($A$7)+1) -> 24 | B30: =IF(A30="","",B29) -> Tổ Hạ tầng Bến Lức | C30: =IF(A30="","",INDIRECT("'DS nhân viên Speedtest'!B"& (2+QUOTIENT(A30-1,16)))) -> Nguyễn Phước Lộc | D30: =IF(A30="","",INDIRECT("'DS nhân viên Speedtest'!C"& (2+QUOTIENT(A30-1,16)))) -> 813232338 | E30: =IF(A30="","",INDIRECT("'DS nhân viên Speedtest'!D"& (2+QUOTIENT(A30-1,16)))) -> locnp.lan@vnpt.vn | F30: =IF(A30="","","Lần "&(MOD(ROW()-ROW($A$7),16)+1)) -> Lần 8 | G30: 46211 | H30: 281 | I30: 46081 | J30: 740 | K30: 29.0 | M30: =IF(B30="","",IF(OR(G30="",H30="",I30=""),0,1)) -> 1 | N30: =IF(B30="","",IF(OR(G30="",J30="",K30=""),0,1)) -> 1 | O30: =IF(B30="","",IF((J30-0)>200,1,0)) -> 1
A31: =IF(INDIRECT("'DS nhân viên Speedtest'!B"& (2+QUOTIENT(ROW()-ROW($A$7),16)))="","",ROW()-ROW($A$7)+1) -> 25 | B31: =IF(A31="","",B30) -> Tổ Hạ tầng Bến Lức | C31: =IF(A31="","",INDIRECT("'DS nhân viên Speedtest'!B"& (2+QUOTIENT(A31-1,16)))) -> Nguyễn Phước Lộc | D31: =IF(A31="","",INDIRECT("'DS nhân viên Speedtest'!C"& (2+QUOTIENT(A31-1,16)))) -> 813232338 | E31: =IF(A31="","",INDIRECT("'DS nhân viên Speedtest'!D"& (2+QUOTIENT(A31-1,16)))) -> locnp.lan@vnpt.vn | F31: =IF(A31="","","Lần "&(MOD(ROW()-ROW($A$7),16)+1)) -> Lần 9 | G31: 46213 | H31: 351 | I31: 72.9 | J31: 659 | K31: 64.8 | M31: =IF(B31="","",IF(OR(G31="",H31="",I31=""),0,1)) -> 1 | N31: =IF(B31="","",IF(OR(G31="",J31="",K31=""),0,1)) -> 1 | O31: =IF(B31="","",IF((J31-0)>200,1,0)) -> 1
A32: =IF(INDIRECT("'DS nhân viên Speedtest'!B"& (2+QUOTIENT(ROW()-ROW($A$7),16)))="","",ROW()-ROW($A$7)+1) -> 26 | B32: =IF(A32="","",B31) -> Tổ Hạ tầng Bến Lức | C32: =IF(A32="","",INDIRECT("'DS nhân viên Speedtest'!B"& (2+QUOTIENT(A32-1,16)))) -> Nguyễn Phước Lộc | D32: =IF(A32="","",INDIRECT("'DS nhân viên Speedtest'!C"& (2+QUOTIENT(A32-1,16)))) -> 813232338 | E32: =IF(A32="","",INDIRECT("'DS nhân viên Speedtest'!D"& (2+QUOTIENT(A32-1,16)))) -> locnp.lan@vnpt.vn | F32: =IF(A32="","","Lần "&(MOD(ROW()-ROW($A$7),16)+1)) -> Lần 10 | G32: 46213 | H32: 260 | I32: 67.9 | J32: 669 | K32: 67.3 | M32: =IF(B32="","",IF(OR(G32="",H32="",I32=""),0,1)) -> 1 | N32: =IF(B32="","",IF(OR(G32="",J32="",K32=""),0,1)) -> 1 | O32: =IF(B32="","",IF((J32-0)>200,1,0)) -> 1
A33: =IF(INDIRECT("'DS nhân viên Speedtest'!B"& (2+QUOTIENT(ROW()-ROW($A$7),16)))="","",ROW()-ROW($A$7)+1) -> 27 | B33: =IF(A33="","",B32) -> Tổ Hạ tầng Bến Lức | C33: =IF(A33="","",INDIRECT("'DS nhân viên Speedtest'!B"& (2+QUOTIENT(A33-1,16)))) -> Nguyễn Phước Lộc | D33: =IF(A33="","",INDIRECT("'DS nhân viên Speedtest'!C"& (2+QUOTIENT(A33-1,16)))) -> 813232338 | E33: =IF(A33="","",INDIRECT("'DS nhân viên Speedtest'!D"& (2+QUOTIENT(A33-1,16)))) -> locnp.lan@vnpt.vn | F33: =IF(A33="","","Lần "&(MOD(ROW()-ROW($A$7),16)+1)) -> Lần 11 | G33: 46213 | H33: 268 | I33: 64.8 | J33: 623 | K33: 64.7 | M33: =IF(B33="","",IF(OR(G33="",H33="",I33=""),0,1)) -> 1 | N33: =IF(B33="","",IF(OR(G33="",J33="",K33=""),0,1)) -> 1 | O33: =IF(B33="","",IF((J33-0)>200,1,0)) -> 1
A34: =IF(INDIRECT("'DS nhân viên Speedtest'!B"& (2+QUOTIENT(ROW()-ROW($A$7),16)))="","",ROW()-ROW($A$7)+1) -> 28 | B34: =IF(A34="","",B33) -> Tổ Hạ tầng Bến Lức | C34: =IF(A34="","",INDIRECT("'DS nhân viên Speedtest'!B"& (2+QUOTIENT(A34-1,16)))) -> Nguyễn Phước Lộc | D34: =IF(A34="","",INDIRECT("'DS nhân viên Speedtest'!C"& (2+QUOTIENT(A34-1,16)))) -> 813232338 | E34: =IF(A34="","",INDIRECT("'DS nhân viên Speedtest'!D"& (2+QUOTIENT(A34-1,16)))) -> locnp.lan@vnpt.vn | F34: =IF(A34="","","Lần "&(MOD(ROW()-ROW($A$7),16)+1)) -> Lần 12 | G34: 46213 | H34: 329 | I34: 73 | J34: 594 | K34: 64.6 | M34: =IF(B34="","",IF(OR(G34="",H34="",I34=""),0,1)) -> 1 | N34: =IF(B34="","",IF(OR(G34="",J34="",K34=""),0,1)) -> 1 | O34: =IF(B34="","",IF((J34-0)>200,1,0)) -> 1
A35: =IF(INDIRECT("'DS nhân viên Speedtest'!B"& (2+QUOTIENT(ROW()-ROW($A$7),16)))="","",ROW()-ROW($A$7)+1) -> 29 | B35: =IF(A35="","",B34) -> Tổ Hạ tầng Bến Lức | C35: =IF(A35="","",INDIRECT("'DS nhân viên Speedtest'!B"& (2+QUOTIENT(A35-1,16)))) -> Nguyễn Phước Lộc | D35: =IF(A35="","",INDIRECT("'DS nhân viên Speedtest'!C"& (2+QUOTIENT(A35-1,16)))) -> 813232338 | E35: =IF(A35="","",INDIRECT("'DS nhân viên Speedtest'!D"& (2+QUOTIENT(A35-1,16)))) -> locnp.lan@vnpt.vn | F35: =IF(A35="","","Lần "&(MOD(ROW()-ROW($A$7),16)+1)) -> Lần 13 | M35: =IF(B35="","",IF(OR(G35="",H35="",I35=""),0,1)) -> 0 | N35: =IF(B35="","",IF(OR(G35="",J35="",K35=""),0,1)) -> 0 | O35: =IF(B35="","",IF((J35-0)>200,1,0)) -> 0
A36: =IF(INDIRECT("'DS nhân viên Speedtest'!B"& (2+QUOTIENT(ROW()-ROW($A$7),16)))="","",ROW()-ROW($A$7)+1) -> 30 | B36: =IF(A36="","",B35) -> Tổ Hạ tầng Bến Lức | C36: =IF(A36="","",INDIRECT("'DS nhân viên Speedtest'!B"& (2+QUOTIENT(A36-1,16)))) -> Nguyễn Phước Lộc | D36: =IF(A36="","",INDIRECT("'DS nhân viên Speedtest'!C"& (2+QUOTIENT(A36-1,16)))) -> 813232338 | E36: =IF(A36="","",INDIRECT("'DS nhân viên Speedtest'!D"& (2+QUOTIENT(A36-1,16)))) -> locnp.lan@vnpt.vn | F36: =IF(A36="","","Lần "&(MOD(ROW()-ROW($A$7),16)+1)) -> Lần 14 | M36: =IF(B36="","",IF(OR(G36="",H36="",I36=""),0,1)) -> 0 | N36: =IF(B36="","",IF(OR(G36="",J36="",K36=""),0,1)) -> 0 | O36: =IF(B36="","",IF((J36-0)>200,1,0)) -> 0
A37: =IF(INDIRECT("'DS nhân viên Speedtest'!B"& (2+QUOTIENT(ROW()-ROW($A$7),16)))="","",ROW()-ROW($A$7)+1) -> 31 | B37: =IF(A37="","",B36) -> Tổ Hạ tầng Bến Lức | C37: =IF(A37="","",INDIRECT("'DS nhân viên Speedtest'!B"& (2+QUOTIENT(A37-1,16)))) -> Nguyễn Phước Lộc | D37: =IF(A37="","",INDIRECT("'DS nhân viên Speedtest'!C"& (2+QUOTIENT(A37-1,16)))) -> 813232338 | E37: =IF(A37="","",INDIRECT("'DS nhân viên Speedtest'!D"& (2+QUOTIENT(A37-1,16)))) -> locnp.lan@vnpt.vn | F37: =IF(A37="","","Lần "&(MOD(ROW()-ROW($A$7),16)+1)) -> Lần 15 | M37: =IF(B37="","",IF(OR(G37="",H37="",I37=""),0,1)) -> 0 | N37: =IF(B37="","",IF(OR(G37="",J37="",K37=""),0,1)) -> 0 | O37: =IF(B37="","",IF((J37-0)>200,1,0)) -> 0
A38: =IF(INDIRECT("'DS nhân viên Speedtest'!B"& (2+QUOTIENT(ROW()-ROW($A$7),16)))="","",ROW()-ROW($A$7)+1) -> 32 | B38: =IF(A38="","",B37) -> Tổ Hạ tầng Bến Lức | C38: =IF(A38="","",INDIRECT("'DS nhân viên Speedtest'!B"& (2+QUOTIENT(A38-1,16)))) -> Nguyễn Phước Lộc | D38: =IF(A38="","",INDIRECT("'DS nhân viên Speedtest'!C"& (2+QUOTIENT(A38-1,16)))) -> 813232338 | E38: =IF(A38="","",INDIRECT("'DS nhân viên Speedtest'!D"& (2+QUOTIENT(A38-1,16)))) -> locnp.lan@vnpt.vn | F38: =IF(A38="","","Lần "&(MOD(ROW()-ROW($A$7),16)+1)) -> Lần 16 | M38: =IF(B38="","",IF(OR(G38="",H38="",I38=""),0,1)) -> 0 | N38: =IF(B38="","",IF(OR(G38="",J38="",K38=""),0,1)) -> 0 | O38: =IF(B38="","",IF((J38-0)>200,1,0)) -> 0
A39: =IF(INDIRECT("'DS nhân viên Speedtest'!B"& (2+QUOTIENT(ROW()-ROW($A$7),16)))="","",ROW()-ROW($A$7)+1) -> 33 | B39: =IF(A39="","",B38) -> Tổ Hạ tầng Bến Lức | C39: =IF(A39="","",INDIRECT("'DS nhân viên Speedtest'!B"& (2+QUOTIENT(A39-1,16)))) -> Nguyễn Khương Minh | D39: =IF(A39="","",INDIRECT("'DS nhân viên Speedtest'!C"& (2+QUOTIENT(A39-1,16)))) -> 913443091 | E39: =IF(A39="","",INDIRECT("'DS nhân viên Speedtest'!D"& (2+QUOTIENT(A39-1,16)))) -> minhnk.lan@vnpt.vn | F39: =IF(A39="","","Lần "&(MOD(ROW()-ROW($A$7),16)+1)) -> Lần 1 | G39: 46204 | H39: 275 | I39: 102 | J39: 480 | K39: 135 | M39: =IF(B39="","",IF(OR(G39="",H39="",I39=""),0,1)) -> 1 | N39: =IF(B39="","",IF(OR(G39="",J39="",K39=""),0,1)) -> 1 | O39: =IF(B39="","",IF((J39-0)>200,1,0)) -> 1
A40: =IF(INDIRECT("'DS nhân viên Speedtest'!B"& (2+QUOTIENT(ROW()-ROW($A$7),16)))="","",ROW()-ROW($A$7)+1) -> 34 | B40: =IF(A40="","",B39) -> Tổ Hạ tầng Bến Lức | C40: =IF(A40="","",INDIRECT("'DS nhân viên Speedtest'!B"& (2+QUOTIENT(A40-1,16)))) -> Nguyễn Khương Minh | D40: =IF(A40="","",INDIRECT("'DS nhân viên Speedtest'!C"& (2+QUOTIENT(A40-1,16)))) -> 913443091 | E40: =IF(A40="","",INDIRECT("'DS nhân viên Speedtest'!D"& (2+QUOTIENT(A40-1,16)))) -> minhnk.lan@vnpt.vn | F40: =IF(A40="","","Lần "&(MOD(ROW()-ROW($A$7),16)+1)) -> Lần 2 | G40: 46204 | H40: 225 | I40: 101 | J40: 444 | K40: 80 | M40: =IF(B40="","",IF(OR(G40="",H40="",I40=""),0,1)) -> 1 | N40: =IF(B40="","",IF(OR(G40="",J40="",K40=""),0,1)) -> 1 | O40: =IF(B40="","",IF((J40-0)>200,1,0)) -> 1
...

Sheet Tổ Gò Dầu
A1: ='Tổ Bến Lức'!A1 -> TRUNG TÂM HẠ TẦNG Kỳ báo cáo: tháng 07 năm 2026 | M1: Kết quả đo (Không điền cột này) | O1: Tổng mẫu đã đo
O2: =COUNTA(J7:J294) -> 180
O3: Tỉ lệ mẫu đo 5G
O4: =IF(O2=0,0,O6/O2) -> 0.21666667
A5: STT | B5: Tổ Hạ Tầng | C5: Tên người thực hiện | D5: SĐT-TEST | E5: Email | F5: Lần đo | G5: Ngày đo DD/MM/YY | H5: i-Speed | J5: SpeedTest | L5: Ghi chú | M5: i-Speed | N5: SpeedTest | O5: 5G
H6: Tốc độ Download | I6: Tốc độ Upload | J6: Tốc độ Download | K6: Tốc độ Upload | M6: =SUM(M7:M470) -> 180 | N6: =SUM(N7:N470) -> 180 | O6: =SUM(O7:O999) -> 39
A7: =IF(INDIRECT("'DS nhân viên Speedtest'!B"& (38+QUOTIENT(ROW()-ROW($A$7),16)))="","",ROW()-ROW($A$7)+1) -> 1 | B7: =IF(A7="","","Tổ Hạ tầng " & 'Báo cáo'!B4) -> Tổ Hạ tầng Gò Dầu | C7: =IF(A7="","",INDIRECT("'DS nhân viên Speedtest'!B"& (38+QUOTIENT(A7-1,16)))) -> Nguyễn Hiếu Khương | D7: =IF(A7="","",INDIRECT("'DS nhân viên Speedtest'!C"& (38+QUOTIENT(A7-1,16)))) -> 942900404 | E7: =IF(A7="","",INDIRECT("'DS nhân viên Speedtest'!D"& (38+QUOTIENT(A7-1,16)))) -> khuongnh.tnh@vnpt.vn | F7: =IF(A7="","","Lần "&(MOD(ROW()-ROW($A$7),16)+1)) -> Lần 1 | G7: 46206 | H7: 167 | I7: 59 | J7: 159 | K7: 63 | M7: =IF(B7="","",IF(OR(G7="",H7="",I7=""),0,1)) -> 1 | N7: =IF(B7="","",IF(OR(G7="",J7="",K7=""),0,1)) -> 1 | O7: =IF(B7="","",IF((J7-0)>200,1,0)) -> 0
A8: =IF(INDIRECT("'DS nhân viên Speedtest'!B"& (38+QUOTIENT(ROW()-ROW($A$7),16)))="","",ROW()-ROW($A$7)+1) -> 2 | B8: =IF(A8="","",B7) -> Tổ Hạ tầng Gò Dầu | C8: =IF(A8="","",INDIRECT("'DS nhân viên Speedtest'!B"& (38+QUOTIENT(A8-1,16)))) -> Nguyễn Hiếu Khương | D8: =IF(A8="","",INDIRECT("'DS nhân viên Speedtest'!C"& (38+QUOTIENT(A8-1,16)))) -> 942900404 | E8: =IF(A8="","",INDIRECT("'DS nhân viên Speedtest'!D"& (38+QUOTIENT(A8-1,16)))) -> khuongnh.tnh@vnpt.vn | F8: =IF(A8="","","Lần "&(MOD(ROW()-ROW($A$7),16)+1)) -> Lần 2 | G8: 46206 | H8: 77 | I8: 61 | J8: 256 | K8: 61 | M8: =IF(B8="","",IF(OR(G8="",H8="",I8=""),0,1)) -> 1 | N8: =IF(B8="","",IF(OR(G8="",J8="",K8=""),0,1)) -> 1 | O8: =IF(B8="","",IF((J8-0)>200,1,0)) -> 1
A9: =IF(INDIRECT("'DS nhân viên Speedtest'!B"& (38+QUOTIENT(ROW()-ROW($A$7),16)))="","",ROW()-ROW($A$7)+1) -> 3 | B9: =IF(A9="","",B8) -> Tổ Hạ tầng Gò Dầu | C9: =IF(A9="","",INDIRECT("'DS nhân viên Speedtest'!B"& (38+QUOTIENT(A9-1,16)))) -> Nguyễn Hiếu Khương | D9: =IF(A9="","",INDIRECT("'DS nhân viên Speedtest'!C"& (38+QUOTIENT(A9-1,16)))) -> 942900404 | E9: =IF(A9="","",INDIRECT("'DS nhân viên Speedtest'!D"& (38+QUOTIENT(A9-1,16)))) -> khuongnh.tnh@vnpt.vn | F9: =IF(A9="","","Lần "&(MOD(ROW()-ROW($A$7),16)+1)) -> Lần 3 | G9: 46206 | H9: 197 | I9: 63 | J9: 255 | K9: 64 | M9: =IF(B9="","",IF(OR(G9="",H9="",I9=""),0,1)) -> 1 | N9: =IF(B9="","",IF(OR(G9="",J9="",K9=""),0,1)) -> 1 | O9: =IF(B9="","",IF((J9-0)>200,1,0)) -> 1
A10: =IF(INDIRECT("'DS nhân viên Speedtest'!B"& (38+QUOTIENT(ROW()-ROW($A$7),16)))="","",ROW()-ROW($A$7)+1) -> 4 | B10: =IF(A10="","",B9) -> Tổ Hạ tầng Gò Dầu | C10: =IF(A10="","",INDIRECT("'DS nhân viên Speedtest'!B"& (38+QUOTIENT(A10-1,16)))) -> Nguyễn Hiếu Khương | D10: =IF(A10="","",INDIRECT("'DS nhân viên Speedtest'!C"& (38+QUOTIENT(A10-1,16)))) -> 942900404 | E10: =IF(A10="","",INDIRECT("'DS nhân viên Speedtest'!D"& (38+QUOTIENT(A10-1,16)))) -> khuongnh.tnh@vnpt.vn | F10: =IF(A10="","","Lần "&(MOD(ROW()-ROW($A$7),16)+1)) -> Lần 4 | G10: 46206 | H10: 116 | I10: 57 | J10: 243 | K10: 61 | M10: =IF(B10="","",IF(OR(G10="",H10="",I10=""),0,1)) -> 1 | N10: =IF(B10="","",IF(OR(G10="",J10="",K10=""),0,1)) -> 1 | O10: =IF(B10="","",IF((J10-0)>200,1,0)) -> 1
A11: =IF(INDIRECT("'DS nhân viên Speedtest'!B"& (38+QUOTIENT(ROW()-ROW($A$7),16)))="","",ROW()-ROW($A$7)+1) -> 5 | B11: =IF(A11="","",B10) -> Tổ Hạ tầng Gò Dầu | C11: =IF(A11="","",INDIRECT("'DS nhân viên Speedtest'!B"& (38+QUOTIENT(A11-1,16)))) -> Nguyễn Hiếu Khương | D11: =IF(A11="","",INDIRECT("'DS nhân viên Speedtest'!C"& (38+QUOTIENT(A11-1,16)))) -> 942900404 | E11: =IF(A11="","",INDIRECT("'DS nhân viên Speedtest'!D"& (38+QUOTIENT(A11-1,16)))) -> khuongnh.tnh@vnpt.vn | F11: =IF(A11="","","Lần "&(MOD(ROW()-ROW($A$7),16)+1)) -> Lần 5 | G11: 46211 | H11: 121 | I11: 60 | J11: 154 | K11: 63 | M11: =IF(B11="","",IF(OR(G11="",H11="",I11=""),0,1)) -> 1 | N11: =IF(B11="","",IF(OR(G11="",J11="",K11=""),0,1)) -> 1 | O11: =IF(B11="","",IF((J11-0)>200,1,0)) -> 0
A12: =IF(INDIRECT("'DS nhân viên Speedtest'!B"& (38+QUOTIENT(ROW()-ROW($A$7),16)))="","",ROW()-ROW($A$7)+1) -> 6 | B12: =IF(A12="","",B11) -> Tổ Hạ tầng Gò Dầu | C12: =IF(A12="","",INDIRECT("'DS nhân viên Speedtest'!B"& (38+QUOTIENT(A12-1,16)))) -> Nguyễn Hiếu Khương | D12: =IF(A12="","",INDIRECT("'DS nhân viên Speedtest'!C"& (38+QUOTIENT(A12-1,16)))) -> 942900404 | E12: =IF(A12="","",INDIRECT("'DS nhân viên Speedtest'!D"& (38+QUOTIENT(A12-1,16)))) -> khuongnh.tnh@vnpt.vn | F12: =IF(A12="","","Lần "&(MOD(ROW()-ROW($A$7),16)+1)) -> Lần 6 | G12: 46211 | H12: 75 | I12: 61 | J12: 187 | K12: 54 | M12: =IF(B12="","",IF(OR(G12="",H12="",I12=""),0,1)) -> 1 | N12: =IF(B12="","",IF(OR(G12="",J12="",K12=""),0,1)) -> 1 | O12: =IF(B12="","",IF((J12-0)>200,1,0)) -> 0
A13: =IF(INDIRECT("'DS nhân viên Speedtest'!B"& (38+QUOTIENT(ROW()-ROW($A$7),16)))="","",ROW()-ROW($A$7)+1) -> 7 | B13: =IF(A13="","",B12) -> Tổ Hạ tầng Gò Dầu | C13: =IF(A13="","",INDIRECT("'DS nhân viên Speedtest'!B"& (38+QUOTIENT(A13-1,16)))) -> Nguyễn Hiếu Khương | D13: =IF(A13="","",INDIRECT("'DS nhân viên Speedtest'!C"& (38+QUOTIENT(A13-1,16)))) -> 942900404 | E13: =IF(A13="","",INDIRECT("'DS nhân viên Speedtest'!D"& (38+QUOTIENT(A13-1,16)))) -> khuongnh.tnh@vnpt.vn | F13: =IF(A13="","","Lần "&(MOD(ROW()-ROW($A$7),16)+1)) -> Lần 7 | G13: 46211 | H13: 170 | I13: 60 | J13: 265 | K13: 50 | M13: =IF(B13="","",IF(OR(G13="",H13="",I13=""),0,1)) -> 1 | N13: =IF(B13="","",IF(OR(G13="",J13="",K13=""),0,1)) -> 1 | O13: =IF(B13="","",IF((J13-0)>200,1,0)) -> 1
A14: =IF(INDIRECT("'DS nhân viên Speedtest'!B"& (38+QUOTIENT(ROW()-ROW($A$7),16)))="","",ROW()-ROW($A$7)+1) -> 8 | B14: =IF(A14="","",B13) -> Tổ Hạ tầng Gò Dầu | C14: =IF(A14="","",INDIRECT("'DS nhân viên Speedtest'!B"& (38+QUOTIENT(A14-1,16)))) -> Nguyễn Hiếu Khương | D14: =IF(A14="","",INDIRECT("'DS nhân viên Speedtest'!C"& (38+QUOTIENT(A14-1,16)))) -> 942900404 | E14: =IF(A14="","",INDIRECT("'DS nhân viên Speedtest'!D"& (38+QUOTIENT(A14-1,16)))) -> khuongnh.tnh@vnpt.vn | F14: =IF(A14="","","Lần "&(MOD(ROW()-ROW($A$7),16)+1)) -> Lần 8 | G14: 46211 | H14: 181 | I14: 61 | J14: 193 | K14: 56 | M14: =IF(B14="","",IF(OR(G14="",H14="",I14=""),0,1)) -> 1 | N14: =IF(B14="","",IF(OR(G14="",J14="",K14=""),0,1)) -> 1 | O14: =IF(B14="","",IF((J14-0)>200,1,0)) -> 0
A15: =IF(INDIRECT("'DS nhân viên Speedtest'!B"& (38+QUOTIENT(ROW()-ROW($A$7),16)))="","",ROW()-ROW($A$7)+1) -> 9 | B15: =IF(A15="","",B14) -> Tổ Hạ tầng Gò Dầu | C15: =IF(A15="","",INDIRECT("'DS nhân viên Speedtest'!B"& (38+QUOTIENT(A15-1,16)))) -> Nguyễn Hiếu Khương | D15: =IF(A15="","",INDIRECT("'DS nhân viên Speedtest'!C"& (38+QUOTIENT(A15-1,16)))) -> 942900404 | E15: =IF(A15="","",INDIRECT("'DS nhân viên Speedtest'!D"& (38+QUOTIENT(A15-1,16)))) -> khuongnh.tnh@vnpt.vn | F15: =IF(A15="","","Lần "&(MOD(ROW()-ROW($A$7),16)+1)) -> Lần 9 | G15: 46217 | H15: 140 | I15: 59 | J15: 206 | K15: 38 | M15: =IF(B15="","",IF(OR(G15="",H15="",I15=""),0,1)) -> 1 | N15: =IF(B15="","",IF(OR(G15="",J15="",K15=""),0,1)) -> 1 | O15: =IF(B15="","",IF((J15-0)>200,1,0)) -> 1
A16: =IF(INDIRECT("'DS nhân viên Speedtest'!B"& (38+QUOTIENT(ROW()-ROW($A$7),16)))="","",ROW()-ROW($A$7)+1) -> 10 | B16: =IF(A16="","",B15) -> Tổ Hạ tầng Gò Dầu | C16: =IF(A16="","",INDIRECT("'DS nhân viên Speedtest'!B"& (38+QUOTIENT(A16-1,16)))) -> Nguyễn Hiếu Khương | D16: =IF(A16="","",INDIRECT("'DS nhân viên Speedtest'!C"& (38+QUOTIENT(A16-1,16)))) -> 942900404 | E16: =IF(A16="","",INDIRECT("'DS nhân viên Speedtest'!D"& (38+QUOTIENT(A16-1,16)))) -> khuongnh.tnh@vnpt.vn | F16: =IF(A16="","","Lần "&(MOD(ROW()-ROW($A$7),16)+1)) -> Lần 10 | G16: 46217 | H16: 167 | I16: 61 | J16: 193 | K16: 43 | M16: =IF(B16="","",IF(OR(G16="",H16="",I16=""),0,1)) -> 1 | N16: =IF(B16="","",IF(OR(G16="",J16="",K16=""),0,1)) -> 1 | O16: =IF(B16="","",IF((J16-0)>200,1,0)) -> 0
A17: =IF(INDIRECT("'DS nhân viên Speedtest'!B"& (38+QUOTIENT(ROW()-ROW($A$7),16)))="","",ROW()-ROW($A$7)+1) -> 11 | B17: =IF(A17="","",B16) -> Tổ Hạ tầng Gò Dầu | C17: =IF(A17="","",INDIRECT("'DS nhân viên Speedtest'!B"& (38+QUOTIENT(A17-1,16)))) -> Nguyễn Hiếu Khương | D17: =IF(A17="","",INDIRECT("'DS nhân viên Speedtest'!C"& (38+QUOTIENT(A17-1,16)))) -> 942900404 | E17: =IF(A17="","",INDIRECT("'DS nhân viên Speedtest'!D"& (38+QUOTIENT(A17-1,16)))) -> khuongnh.tnh@vnpt.vn | F17: =IF(A17="","","Lần "&(MOD(ROW()-ROW($A$7),16)+1)) -> Lần 11 | G17: 46217 | H17: 163 | I17: 59 | J17: 154 | K17: 63 | M17: =IF(B17="","",IF(OR(G17="",H17="",I17=""),0,1)) -> 1 | N17: =IF(B17="","",IF(OR(G17="",J17="",K17=""),0,1)) -> 1 | O17: =IF(B17="","",IF((J17-0)>200,1,0)) -> 0
A18: =IF(INDIRECT("'DS nhân viên Speedtest'!B"& (38+QUOTIENT(ROW()-ROW($A$7),16)))="","",ROW()-ROW($A$7)+1) -> 12 | B18: =IF(A18="","",B17) -> Tổ Hạ tầng Gò Dầu | C18: =IF(A18="","",INDIRECT("'DS nhân viên Speedtest'!B"& (38+QUOTIENT(A18-1,16)))) -> Nguyễn Hiếu Khương | D18: =IF(A18="","",INDIRECT("'DS nhân viên Speedtest'!C"& (38+QUOTIENT(A18-1,16)))) -> 942900404 | E18: =IF(A18="","",INDIRECT("'DS nhân viên Speedtest'!D"& (38+QUOTIENT(A18-1,16)))) -> khuongnh.tnh@vnpt.vn | F18: =IF(A18="","","Lần "&(MOD(ROW()-ROW($A$7),16)+1)) -> Lần 12 | G18: 46217 | H18: 169 | I18: 57 | J18: 187 | K18: 54 | M18: =IF(B18="","",IF(OR(G18="",H18="",I18=""),0,1)) -> 1 | N18: =IF(B18="","",IF(OR(G18="",J18="",K18=""),0,1)) -> 1 | O18: =IF(B18="","",IF((J18-0)>200,1,0)) -> 0
A19: =IF(INDIRECT("'DS nhân viên Speedtest'!B"& (38+QUOTIENT(ROW()-ROW($A$7),16)))="","",ROW()-ROW($A$7)+1) -> 13 | B19: =IF(A19="","",B18) -> Tổ Hạ tầng Gò Dầu | C19: =IF(A19="","",INDIRECT("'DS nhân viên Speedtest'!B"& (38+QUOTIENT(A19-1,16)))) -> Nguyễn Hiếu Khương | D19: =IF(A19="","",INDIRECT("'DS nhân viên Speedtest'!C"& (38+QUOTIENT(A19-1,16)))) -> 942900404 | E19: =IF(A19="","",INDIRECT("'DS nhân viên Speedtest'!D"& (38+QUOTIENT(A19-1,16)))) -> khuongnh.tnh@vnpt.vn | F19: =IF(A19="","","Lần "&(MOD(ROW()-ROW($A$7),16)+1)) -> Lần 13 | G19: 46223 | M19: =IF(B19="","",IF(OR(G19="",H19="",I19=""),0,1)) -> 0 | N19: =IF(B19="","",IF(OR(G19="",J19="",K19=""),0,1)) -> 0 | O19: =IF(B19="","",IF((J19-0)>200,1,0)) -> 0
A20: =IF(INDIRECT("'DS nhân viên Speedtest'!B"& (38+QUOTIENT(ROW()-ROW($A$7),16)))="","",ROW()-ROW($A$7)+1) -> 14 | B20: =IF(A20="","",B19) -> Tổ Hạ tầng Gò Dầu | C20: =IF(A20="","",INDIRECT("'DS nhân viên Speedtest'!B"& (38+QUOTIENT(A20-1,16)))) -> Nguyễn Hiếu Khương | D20: =IF(A20="","",INDIRECT("'DS nhân viên Speedtest'!C"& (38+QUOTIENT(A20-1,16)))) -> 942900404 | E20: =IF(A20="","",INDIRECT("'DS nhân viên Speedtest'!D"& (38+QUOTIENT(A20-1,16)))) -> khuongnh.tnh@vnpt.vn | F20: =IF(A20="","","Lần "&(MOD(ROW()-ROW($A$7),16)+1)) -> Lần 14 | G20: 46223 | M20: =IF(B20="","",IF(OR(G20="",H20="",I20=""),0,1)) -> 0 | N20: =IF(B20="","",IF(OR(G20="",J20="",K20=""),0,1)) -> 0 | O20: =IF(B20="","",IF((J20-0)>200,1,0)) -> 0
A21: =IF(INDIRECT("'DS nhân viên Speedtest'!B"& (38+QUOTIENT(ROW()-ROW($A$7),16)))="","",ROW()-ROW($A$7)+1) -> 15 | B21: =IF(A21="","",B20) -> Tổ Hạ tầng Gò Dầu | C21: =IF(A21="","",INDIRECT("'DS nhân viên Speedtest'!B"& (38+QUOTIENT(A21-1,16)))) -> Nguyễn Hiếu Khương | D21: =IF(A21="","",INDIRECT("'DS nhân viên Speedtest'!C"& (38+QUOTIENT(A21-1,16)))) -> 942900404 | E21: =IF(A21="","",INDIRECT("'DS nhân viên Speedtest'!D"& (38+QUOTIENT(A21-1,16)))) -> khuongnh.tnh@vnpt.vn | F21: =IF(A21="","","Lần "&(MOD(ROW()-ROW($A$7),16)+1)) -> Lần 15 | G21: 46223 | M21: =IF(B21="","",IF(OR(G21="",H21="",I21=""),0,1)) -> 0 | N21: =IF(B21="","",IF(OR(G21="",J21="",K21=""),0,1)) -> 0 | O21: =IF(B21="","",IF((J21-0)>200,1,0)) -> 0
A22: =IF(INDIRECT("'DS nhân viên Speedtest'!B"& (38+QUOTIENT(ROW()-ROW($A$7),16)))="","",ROW()-ROW($A$7)+1) -> 16 | B22: =IF(A22="","",B21) -> Tổ Hạ tầng Gò Dầu | C22: =IF(A22="","",INDIRECT("'DS nhân viên Speedtest'!B"& (38+QUOTIENT(A22-1,16)))) -> Nguyễn Hiếu Khương | D22: =IF(A22="","",INDIRECT("'DS nhân viên Speedtest'!C"& (38+QUOTIENT(A22-1,16)))) -> 942900404 | E22: =IF(A22="","",INDIRECT("'DS nhân viên Speedtest'!D"& (38+QUOTIENT(A22-1,16)))) -> khuongnh.tnh@vnpt.vn | F22: =IF(A22="","","Lần "&(MOD(ROW()-ROW($A$7),16)+1)) -> Lần 16 | G22: 46223 | M22: =IF(B22="","",IF(OR(G22="",H22="",I22=""),0,1)) -> 0 | N22: =IF(B22="","",IF(OR(G22="",J22="",K22=""),0,1)) -> 0 | O22: =IF(B22="","",IF((J22-0)>200,1,0)) -> 0
A23: =IF(INDIRECT("'DS nhân viên Speedtest'!B"& (38+QUOTIENT(ROW()-ROW($A$7),16)))="","",ROW()-ROW($A$7)+1) -> 17 | B23: =IF(A23="","",B22) -> Tổ Hạ tầng Gò Dầu | C23: =IF(A23="","",INDIRECT("'DS nhân viên Speedtest'!B"& (38+QUOTIENT(A23-1,16)))) -> Nguyễn Phan Duy An | D23: =IF(A23="","",INDIRECT("'DS nhân viên Speedtest'!C"& (38+QUOTIENT(A23-1,16)))) -> 888444008 | E23: =IF(A23="","",INDIRECT("'DS nhân viên Speedtest'!D"& (38+QUOTIENT(A23-1,16)))) -> x | F23: =IF(A23="","","Lần "&(MOD(ROW()-ROW($A$7),16)+1)) -> Lần 1 | G23: 46206 | H23: 132 | I23: 52 | J23: 161 | K23: 61 | M23: =IF(B23="","",IF(OR(G23="",H23="",I23=""),0,1)) -> 1 | N23: =IF(B23="","",IF(OR(G23="",J23="",K23=""),0,1)) -> 1 | O23: =IF(B23="","",IF((J23-0)>200,1,0)) -> 0
A24: =IF(INDIRECT("'DS nhân viên Speedtest'!B"& (38+QUOTIENT(ROW()-ROW($A$7),16)))="","",ROW()-ROW($A$7)+1) -> 18 | B24: =IF(A24="","",B23) -> Tổ Hạ tầng Gò Dầu | C24: =IF(A24="","",INDIRECT("'DS nhân viên Speedtest'!B"& (38+QUOTIENT(A24-1,16)))) -> Nguyễn Phan Duy An | D24: =IF(A24="","",INDIRECT("'DS nhân viên Speedtest'!C"& (38+QUOTIENT(A24-1,16)))) -> 888444008 | E24: =IF(A24="","",INDIRECT("'DS nhân viên Speedtest'!D"& (38+QUOTIENT(A24-1,16)))) -> x | F24: =IF(A24="","","Lần "&(MOD(ROW()-ROW($A$7),16)+1)) -> Lần 2 | G24: 46206 | H24: 89 | I24: 37 | J24: 154 | K24: 61 | M24: =IF(B24="","",IF(OR(G24="",H24="",I24=""),0,1)) -> 1 | N24: =IF(B24="","",IF(OR(G24="",J24="",K24=""),0,1)) -> 1 | O24: =IF(B24="","",IF((J24-0)>200,1,0)) -> 0
A25: =IF(INDIRECT("'DS nhân viên Speedtest'!B"& (38+QUOTIENT(ROW()-ROW($A$7),16)))="","",ROW()-ROW($A$7)+1) -> 19 | B25: =IF(A25="","",B24) -> Tổ Hạ tầng Gò Dầu | C25: =IF(A25="","",INDIRECT("'DS nhân viên Speedtest'!B"& (38+QUOTIENT(A25-1,16)))) -> Nguyễn Phan Duy An | D25: =IF(A25="","",INDIRECT("'DS nhân viên Speedtest'!C"& (38+QUOTIENT(A25-1,16)))) -> 888444008 | E25: =IF(A25="","",INDIRECT("'DS nhân viên Speedtest'!D"& (38+QUOTIENT(A25-1,16)))) -> x | F25: =IF(A25="","","Lần "&(MOD(ROW()-ROW($A$7),16)+1)) -> Lần 3 | G25: 46206 | H25: 75 | I25: 15 | J25: 149 | K25: 59 | M25: =IF(B25="","",IF(OR(G25="",H25="",I25=""),0,1)) -> 1 | N25: =IF(B25="","",IF(OR(G25="",J25="",K25=""),0,1)) -> 1 | O25: =IF(B25="","",IF((J25-0)>200,1,0)) -> 0
A26: =IF(INDIRECT("'DS nhân viên Speedtest'!B"& (38+QUOTIENT(ROW()-ROW($A$7),16)))="","",ROW()-ROW($A$7)+1) -> 20 | B26: =IF(A26="","",B25) -> Tổ Hạ tầng Gò Dầu | C26: =IF(A26="","",INDIRECT("'DS nhân viên Speedtest'!B"& (38+QUOTIENT(A26-1,16)))) -> Nguyễn Phan Duy An | D26: =IF(A26="","",INDIRECT("'DS nhân viên Speedtest'!C"& (38+QUOTIENT(A26-1,16)))) -> 888444008 | E26: =IF(A26="","",INDIRECT("'DS nhân viên Speedtest'!D"& (38+QUOTIENT(A26-1,16)))) -> x | F26: =IF(A26="","","Lần "&(MOD(ROW()-ROW($A$7),16)+1)) -> Lần 4 | G26: 46206 | H26: 94 | I26: 52 | J26: 148 | K26: 60 | M26: =IF(B26="","",IF(OR(G26="",H26="",I26=""),0,1)) -> 1 | N26: =IF(B26="","",IF(OR(G26="",J26="",K26=""),0,1)) -> 1 | O26: =IF(B26="","",IF((J26-0)>200,1,0)) -> 0
A27: =IF(INDIRECT("'DS nhân viên Speedtest'!B"& (38+QUOTIENT(ROW()-ROW($A$7),16)))="","",ROW()-ROW($A$7)+1) -> 21 | B27: =IF(A27="","",B26) -> Tổ Hạ tầng Gò Dầu | C27: =IF(A27="","",INDIRECT("'DS nhân viên Speedtest'!B"& (38+QUOTIENT(A27-1,16)))) -> Nguyễn Phan Duy An | D27: =IF(A27="","",INDIRECT("'DS nhân viên Speedtest'!C"& (38+QUOTIENT(A27-1,16)))) -> 888444008 | E27: =IF(A27="","",INDIRECT("'DS nhân viên Speedtest'!D"& (38+QUOTIENT(A27-1,16)))) -> x | F27: =IF(A27="","","Lần "&(MOD(ROW()-ROW($A$7),16)+1)) -> Lần 5 | G27: 46211 | H27: 162 | I27: 62 | J27: 146 | K27: 61 | M27: =IF(B27="","",IF(OR(G27="",H27="",I27=""),0,1)) -> 1 | N27: =IF(B27="","",IF(OR(G27="",J27="",K27=""),0,1)) -> 1 | O27: =IF(B27="","",IF((J27-0)>200,1,0)) -> 0
A28: =IF(INDIRECT("'DS nhân viên Speedtest'!B"& (38+QUOTIENT(ROW()-ROW($A$7),16)))="","",ROW()-ROW($A$7)+1) -> 22 | B28: =IF(A28="","",B27) -> Tổ Hạ tầng Gò Dầu | C28: =IF(A28="","",INDIRECT("'DS nhân viên Speedtest'!B"& (38+QUOTIENT(A28-1,16)))) -> Nguyễn Phan Duy An | D28: =IF(A28="","",INDIRECT("'DS nhân viên Speedtest'!C"& (38+QUOTIENT(A28-1,16)))) -> 888444008 | E28: =IF(A28="","",INDIRECT("'DS nhân viên Speedtest'!D"& (38+QUOTIENT(A28-1,16)))) -> x | F28: =IF(A28="","","Lần "&(MOD(ROW()-ROW($A$7),16)+1)) -> Lần 6 | G28: 46211 | H28: 147 | I28: 64 | J28: 146 | K28: 61 | M28: =IF(B28="","",IF(OR(G28="",H28="",I28=""),0,1)) -> 1 | N28: =IF(B28="","",IF(OR(G28="",J28="",K28=""),0,1)) -> 1 | O28: =IF(B28="","",IF((J28-0)>200,1,0)) -> 0
A29: =IF(INDIRECT("'DS nhân viên Speedtest'!B"& (38+QUOTIENT(ROW()-ROW($A$7),16)))="","",ROW()-ROW($A$7)+1) -> 23 | B29: =IF(A29="","",B28) -> Tổ Hạ tầng Gò Dầu | C29: =IF(A29="","",INDIRECT("'DS nhân viên Speedtest'!B"& (38+QUOTIENT(A29-1,16)))) -> Nguyễn Phan Duy An | D29: =IF(A29="","",INDIRECT("'DS nhân viên Speedtest'!C"& (38+QUOTIENT(A29-1,16)))) -> 888444008 | E29: =IF(A29="","",INDIRECT("'DS nhân viên Speedtest'!D"& (38+QUOTIENT(A29-1,16)))) -> x | F29: =IF(A29="","","Lần "&(MOD(ROW()-ROW($A$7),16)+1)) -> Lần 7 | G29: 46211 | H29: 139 | I29: 60 | J29: 145 | K29: 61 | M29: =IF(B29="","",IF(OR(G29="",H29="",I29=""),0,1)) -> 1 | N29: =IF(B29="","",IF(OR(G29="",J29="",K29=""),0,1)) -> 1 | O29: =IF(B29="","",IF((J29-0)>200,1,0)) -> 0
A30: =IF(INDIRECT("'DS nhân viên Speedtest'!B"& (38+QUOTIENT(ROW()-ROW($A$7),16)))="","",ROW()-ROW($A$7)+1) -> 24 | B30: =IF(A30="","",B29) -> Tổ Hạ tầng Gò Dầu | C30: =IF(A30="","",INDIRECT("'DS nhân viên Speedtest'!B"& (38+QUOTIENT(A30-1,16)))) -> Nguyễn Phan Duy An | D30: =IF(A30="","",INDIRECT("'DS nhân viên Speedtest'!C"& (38+QUOTIENT(A30-1,16)))) -> 888444008 | E30: =IF(A30="","",INDIRECT("'DS nhân viên Speedtest'!D"& (38+QUOTIENT(A30-1,16)))) -> x | F30: =IF(A30="","","Lần "&(MOD(ROW()-ROW($A$7),16)+1)) -> Lần 8 | G30: 46211 | H30: 158 | I30: 59 | J30: 137 | K30: 61 | M30: =IF(B30="","",IF(OR(G30="",H30="",I30=""),0,1)) -> 1 | N30: =IF(B30="","",IF(OR(G30="",J30="",K30=""),0,1)) -> 1 | O30: =IF(B30="","",IF((J30-0)>200,1,0)) -> 0
